Workbook
Name AI: [1]datos!$B$14:$B$57
Name CtrlInt: [1]datos!$V$2:$V$7
Name Cumplimiento: [1]datos!$R$2:$R$7
Name DeptoAI: [1]datos!$G$2:$G$15
Name eef_af: datos!$Z$43:$Z$53
Name eef_br: datos!#REF!
Name Emp: [1]datos!$G$27:$G$34
Name ExistNorma: [1]datos!$T$2:$T$7
Name Impacto: [1]datos!$X$2:$X$7
Name Prioridad1: [1]datos!$P$11:$P$16
Name Proceso: [1]datos!$E$2:$E$6
Name resultado2: '[1](3)_Plan_de_Accion'!$AF$3:$AF$7
Name RiesgoAsoc: [1]datos!$P$2:$P$7
Name subdir1: '[1](3)_Plan_de_Accion'!$AI$3:$AI$6
Name TipoHallazgo: [1]datos!$G$19:$G$23

Sheet (1)_Base_de_Datos
A3: NO. OBS | B3: OBSERVACION / RECOMENDACIÓN | C3: GRADO DE RIESGO | D3: CLASIFICACIÓN DE PROCESO AUDITADO | E3: ÁREA AUDITADA | F3: AÑO DE REVISIÓN | G3: CVE | H3: PERÍODO DE REVISIÓN | I3: REVISION CON CIFRAS AL | J3: NOMBRE DE LA AUDITORIA | K3: NOMBRE DEL MONITOREO | L3: CONCEPTO DEL HALLAZGO | M3: DESCRIPCION DEL HALLAZGO | N3: IMPLICACIÓN | O3: FUNDAMENTO | P3: CONTROL | Q3: TIPO DE HALLAZGO | R3: EMPRESA | S3: DEPTO DE AUDITORÍA INTERNA | T3: AUDITOR RESPONSABLE | U3: Area del Auditor | V3: FECHA DE ELABORACIÓN | W3: NIP | X3: NOMBRE DEL RESPONSABLE AUDITADO | Y3: PUESTO DEL RESPONSABLE AUDITADO | Z3: AREA DEL RESPONSABLE AUDITADO | AA3: DIRECCION RESPONSABLE | AB3: COMPROMISO INICIAL | AC3: FECHA COMPROMISO INICIAL
A4: 01 | B4: Observación | C4: MEDIO | D4: Control | E4: Calificación de Cartera | F4: 2026 | H4: 31 de Mayo de 2026 | I4: 31 de Mayo de 2026 | J4: CALIFICACION DE CARTERA | L4: Inconsistencias en el cálculo de la Probabilidad de Incumplimiento y Severidad de la Pérdida. | M4: a) Como resultado de la validación del cálculo de la Probabilidad de Incumplimiento se detectó un caso GREENING RENOVABLES S.A. DE C.V., que se calificó en sector Servicios debiendo ser Construcción de acuerdo a la carátula de autorización de fecha 15 de septiembre de 2025. b) Diferencia en las reserva de acuerdo a lo siguiente: En 1 cliente inconsistencia en el cálculo de la EI expuesta, después de aplicar la garantía líquida, lo cual se detalla en el reporte regulatorio R04-C-0434 Severidad de la Pérdida, lo que ocasiona cálculo erróneo de la reserva, Impacto $379.83 pesos. | N4: Incumplimiento a la CUB Anexo 22 | O4: CUB Anexo 22, CUB Artículo 114. | P4: Deficiencia del diseño del control | Q4: Diseño del Control Limitado | R4: Banco BASE | S4: Auditoría de Crédito Empresarial | T4: Blanca Nelly Gutiérrez Garza | U4: =IFERROR(VLOOKUP(T4,datos!$W$3:$X$23,2,0),"") | V4: 25 de Septiembre de 2026 | W4: 3731 | X4: =IFERROR(VLOOKUP($W4,Plantilla!$B$3:$AE$2497,2,0),"") | Y4: =IFERROR(VLOOKUP($W4,Plantilla!$B$3:$AE$2497,4,0),"") | Z4: =IFERROR(VLOOKUP($W4,Plantilla!$B$3:$AE$2496,4,0),"") | AA4: =IFERROR(VLOOKUP($W4,Plantilla!$B$3:$AJ$2496,17,0),"") | AB4: =IFERROR(IF('(3)_Plan_de_Accion'!M14<>"",'(3)_Plan_de_Accion'!M14,""),"") | AC4: =IFERROR(IF('(3)_Plan_de_Accion'!Q14<>"",'(3)_Plan_de_Accion'!Q14,""),"")
A5: 02 | B5: Observación | C5: BAJO | D5: Control | E5: Calificación de Cartera | F5: =IFERROR(IF($J5<>"",F4,""),"") | G5: =IFERROR(IF($J5<>"",G4,""),"") | H5: =IFERROR(IF($J5<>"",H4,""),"") | I5: =IFERROR(IF($J5<>"",I4,""),"") | J5: =IFERROR(IF($B5<>"",J4,""),"") | L5: Calidad de la información del Reporte Regulatorio R04-C-438. | M5: Derivado de la validación de la calidad de la información en los reportes regulatorios, en el reporte R04-C-0438, se detectó error el campo 45 Cuentas y Documentos por Cobrar, de acuerdo al instructivo de llenado, si los estados financiero se encuentran vencidos, este campo deberá llenarse con -999, sin embargo se esta presentando en -99. (5 clientes) | N5: Incumplimiento a Regulación Externa | O5: CUB_BD_R04_C-0430-0439_Cred com Act 11feb26 Instructivo | P5: Deficiencia del diseño del control | Q5: Diseño del Control Limitado | R5: =IFERROR(IF($J5<>"",R4,""),"") | S5: =IFERROR(IF($J5<>"",S4,""),"") | T5: =IFERROR(IF($J5<>"",T4,""),"") | U5: =IFERROR(IF($J5<>"",U4,""),"") | V5: =IFERROR(IF($J5<>"",V4,""),"") | W5: 3731 | X5: =IFERROR(VLOOKUP($W5,Plantilla!$B$3:$AE$2497,2,0),"") | Y5: =IFERROR(VLOOKUP($W5,Plantilla!$B$3:$AE$2497,4,0),"") | Z5: =IFERROR(VLOOKUP($W5,Plantilla!$B$3:$AE$2496,4,0),"") | AA5: =IFERROR(VLOOKUP($W5,Plantilla!$B$3:$AJ$2496,17,0),"") | AB5: =IFERROR(IF('(3)_Plan_de_Accion'!M23<>"",'(3)_Plan_de_Accion'!M23,""),"") | AC5: =IFERROR(IF('(3)_Plan_de_Accion'!Q23<>"",'(3)_Plan_de_Accion'!Q23,""),"")
A6: 03 | F6: =IFERROR(IF($J6<>"",F5,""),"") | G6: =IFERROR(IF($J6<>"",G5,""),"") | H6: =IFERROR(IF($J6<>"",H5,""),"") | I6: =IFERROR(IF($J6<>"",I5,""),"") | J6: =IFERROR(IF($B6<>"",J5,""),"") | R6: =IFERROR(IF($J6<>"",R5,""),"") | S6: =IFERROR(IF($J6<>"",S5,""),"") | T6: =IFERROR(IF($J6<>"",T5,""),"") | U6: =IFERROR(IF($J6<>"",U5,""),"") | V6: =IFERROR(IF($J6<>"",V5,""),"") | X6: =IFERROR(VLOOKUP($W6,Plantilla!$B$3:$AE$2497,2,0),"") | Y6: =IFERROR(VLOOKUP($W6,Plantilla!$B$3:$AE$2497,4,0),"") | Z6: =IFERROR(VLOOKUP($W6,Plantilla!$B$3:$AE$2496,4,0),"") | AA6: =IFERROR(VLOOKUP($W6,Plantilla!$B$3:$AJ$2496,17,0),"") | AB6: =IFERROR(IF('(3)_Plan_de_Accion'!M32<>"",'(3)_Plan_de_Accion'!M32,""),"") | AC6: =IFERROR(IF('(3)_Plan_de_Accion'!Q32<>"",'(3)_Plan_de_Accion'!Q32,""),"")
A7: 04 | F7: =IFERROR(IF($J7<>"",F6,""),"") | G7: =IFERROR(IF($J7<>"",G6,""),"") | H7: =IFERROR(IF($J7<>"",H6,""),"") | I7: =IFERROR(IF($J7<>"",I6,""),"") | J7: =IFERROR(IF($B7<>"",J6,""),"") | R7: =IFERROR(IF($J7<>"",R6,""),"") | S7: =IFERROR(IF($J7<>"",S6,""),"") | T7: =IFERROR(IF($J7<>"",T6,""),"") | U7: =IFERROR(IF($J7<>"",U6,""),"") | V7: =IFERROR(IF($J7<>"",V6,""),"") | X7: =IFERROR(VLOOKUP($W7,Plantilla!$B$3:$AE$2497,2,0),"") | Y7: =IFERROR(VLOOKUP($W7,Plantilla!$B$3:$AE$2497,4,0),"") | Z7: =IFERROR(VLOOKUP($W7,Plantilla!$B$3:$AE$2496,4,0),"") | AA7: =IFERROR(VLOOKUP($W7,Plantilla!$B$3:$AJ$2496,17,0),"") | AB7: =IFERROR(IF('(3)_Plan_de_Accion'!M41<>"",'(3)_Plan_de_Accion'!M41,""),"") | AC7: =IFERROR(IF('(3)_Plan_de_Accion'!Q41<>"",'(3)_Plan_de_Accion'!Q41,""),"")
A8: 05 | F8: =IFERROR(IF($J8<>"",F7,""),"") | G8: =IFERROR(IF($J8<>"",G7,""),"") | H8: =IFERROR(IF($J8<>"",H7,""),"") | I8: =IFERROR(IF($J8<>"",I7,""),"") | J8: =IFERROR(IF($B8<>"",J7,""),"") | R8: =IFERROR(IF($J8<>"",R7,""),"") | S8: =IFERROR(IF($J8<>"",S7,""),"") | T8: =IFERROR(IF($J8<>"",T7,""),"") | U8: =IFERROR(IF($J8<>"",U7,""),"") | V8: =IFERROR(IF($J8<>"",V7,""),"") | X8: =IFERROR(VLOOKUP($W8,Plantilla!$B$3:$AE$2497,2,0),"") | Y8: =IFERROR(VLOOKUP($W8,Plantilla!$B$3:$AE$2497,4,0),"") | Z8: =IFERROR(VLOOKUP($W8,Plantilla!$B$3:$AE$2496,4,0),"") | AA8: =IFERROR(VLOOKUP($W8,Plantilla!$B$3:$AJ$2496,17,0),"") | AB8: =IFERROR(IF('(3)_Plan_de_Accion'!M50<>"",'(3)_Plan_de_Accion'!M50,""),"") | AC8: =IFERROR(IF('(3)_Plan_de_Accion'!Q50<>"",'(3)_Plan_de_Accion'!Q50,""),"")
A9: 06 | F9: =IFERROR(IF($J9<>"",F8,""),"") | G9: =IFERROR(IF($J9<>"",G8,""),"") | H9: =IFERROR(IF($J9<>"",H8,""),"") | I9: =IFERROR(IF($J9<>"",I8,""),"") | J9: =IFERROR(IF($B9<>"",J8,""),"") | R9: =IFERROR(IF($J9<>"",R8,""),"") | S9: =IFERROR(IF($J9<>"",S8,""),"") | T9: =IFERROR(IF($J9<>"",T8,""),"") | U9: =IFERROR(IF($J9<>"",U8,""),"") | V9: =IFERROR(IF($J9<>"",V8,""),"") | X9: =IFERROR(VLOOKUP($W9,Plantilla!$B$3:$AE$2497,2,0),"") | Y9: =IFERROR(VLOOKUP($W9,Plantilla!$B$3:$AE$2497,4,0),"") | Z9: =IFERROR(VLOOKUP($W9,Plantilla!$B$3:$AE$2496,4,0),"") | AA9: =IFERROR(VLOOKUP($W9,Plantilla!$B$3:$AJ$2496,17,0),"") | AB9: =IFERROR(IF('(3)_Plan_de_Accion'!M59<>"",'(3)_Plan_de_Accion'!M59,""),"") | AC9: =IFERROR(IF('(3)_Plan_de_Accion'!Q59<>"",'(3)_Plan_de_Accion'!Q59,""),"")
A10: 07 | F10: =IFERROR(IF($J10<>"",F9,""),"") | G10: =IFERROR(IF($J10<>"",G9,""),"") | H10: =IFERROR(IF($J10<>"",H9,""),"") | I10: =IFERROR(IF($J10<>"",I9,""),"") | J10: =IFERROR(IF($B10<>"",J9,""),"") | R10: =IFERROR(IF($J10<>"",R9,""),"") | S10: =IFERROR(IF($J10<>"",S9,""),"") | T10: =IFERROR(IF($J10<>"",T9,""),"") | U10: =IFERROR(IF($J10<>"",U9,""),"") | V10: =IFERROR(IF($J10<>"",V9,""),"") | X10: =IFERROR(VLOOKUP($W10,Plantilla!$B$3:$AE$2497,2,0),"") | Y10: =IFERROR(VLOOKUP($W10,Plantilla!$B$3:$AE$2497,4,0),"") | Z10: =IFERROR(VLOOKUP($W10,Plantilla!$B$3:$AE$2496,4,0),"") | AA10: =IFERROR(VLOOKUP($W10,Plantilla!$B$3:$AJ$2496,17,0),"") | AB10: =IFERROR(IF('(3)_Plan_de_Accion'!M68<>"",'(3)_Plan_de_Accion'!M68,""),"") | AC10: =IFERROR(IF('(3)_Plan_de_Accion'!Q68<>"",'(3)_Plan_de_Accion'!Q68,""),"")
A11: 08 | F11: =IFERROR(IF($J11<>"",F10,""),"") | G11: =IFERROR(IF($J11<>"",G10,""),"") | H11: =IFERROR(IF($J11<>"",H10,""),"") | I11: =IFERROR(IF($J11<>"",I10,""),"") | J11: =IFERROR(IF($B11<>"",J10,""),"") | R11: =IFERROR(IF($J11<>"",R10,""),"") | S11: =IFERROR(IF($J11<>"",S10,""),"") | T11: =IFERROR(IF($J11<>"",T10,""),"") | U11: =IFERROR(IF($J11<>"",U10,""),"") | V11: =IFERROR(IF($J11<>"",V10,""),"") | X11: =IFERROR(VLOOKUP($W11,Plantilla!$B$3:$AE$2497,2,0),"") | Y11: =IFERROR(VLOOKUP($W11,Plantilla!$B$3:$AE$2497,4,0),"") | Z11: =IFERROR(VLOOKUP($W11,Plantilla!$B$3:$AE$2496,4,0),"") | AA11: =IFERROR(VLOOKUP($W11,Plantilla!$B$3:$AJ$2496,17,0),"") | AB11: =IFERROR(IF('(3)_Plan_de_Accion'!M79<>"",'(3)_Plan_de_Accion'!M79,""),"") | AC11: =IFERROR(IF('(3)_Plan_de_Accion'!Q79<>"",'(3)_Plan_de_Accion'!Q79,""),"")
A12: 09 | F12: =IFERROR(IF($J12<>"",F11,""),"") | G12: =IFERROR(IF($J12<>"",G11,""),"") | H12: =IFERROR(IF($J12<>"",H11,""),"") | I12: =IFERROR(IF($J12<>"",I11,""),"") | J12: =IFERROR(IF($B12<>"",J11,""),"") | R12: =IFERROR(IF($J12<>"",R11,""),"") | S12: =IFERROR(IF($J12<>"",S11,""),"") | T12: =IFERROR(IF($J12<>"",T11,""),"") | U12: =IFERROR(IF($J12<>"",U11,""),"") | V12: =IFERROR(IF($J12<>"",V11,""),"") | X12: =IFERROR(VLOOKUP($W12,Plantilla!$B$3:$AE$2497,2,0),"") | Y12: =IFERROR(VLOOKUP($W12,Plantilla!$B$3:$AE$2497,4,0),"") | Z12: =IFERROR(VLOOKUP($W12,Plantilla!$B$3:$AE$2496,4,0),"") | AA12: =IFERROR(VLOOKUP($W12,Plantilla!$B$3:$AJ$2496,17,0),"") | AB12: =IFERROR(IF('(3)_Plan_de_Accion'!M88<>"",'(3)_Plan_de_Accion'!M88,""),"") | AC12: =IFERROR(IF('(3)_Plan_de_Accion'!Q88<>"",'(3)_Plan_de_Accion'!Q88,""),"")
A13: 10 | F13: =IFERROR(IF($J13<>"",F12,""),"") | G13: =IFERROR(IF($J13<>"",G12,""),"") | H13: =IFERROR(IF($J13<>"",H12,""),"") | I13: =IFERROR(IF($J13<>"",I12,""),"") | J13: =IFERROR(IF($B13<>"",J12,""),"") | R13: =IFERROR(IF($J13<>"",R12,""),"") | S13: =IFERROR(IF($J13<>"",S12,""),"") | T13: =IFERROR(IF($J13<>"",T12,""),"") | U13: =IFERROR(IF($J13<>"",U12,""),"") | V13: =IFERROR(IF($J13<>"",V12,""),"") | X13: =IFERROR(VLOOKUP($W13,Plantilla!$B$3:$AE$2497,2,0),"") | Y13: =IFERROR(VLOOKUP($W13,Plantilla!$B$3:$AE$2497,4,0),"") | Z13: =IFERROR(VLOOKUP($W13,Plantilla!$B$3:$AE$2496,4,0),"") | AA13: =IFERROR(VLOOKUP($W13,Plantilla!$B$3:$AJ$2496,17,0),"") | AB13: =IFERROR(IF('(3)_Plan_de_Accion'!M97<>"",'(3)_Plan_de_Accion'!M97,""),"") | AC13: =IFERROR(IF('(3)_Plan_de_Accion'!Q97<>"",'(3)_Plan_de_Accion'!Q97,""),"")
A14: 11 | F14: =IFERROR(IF($J14<>"",F13,""),"") | G14: =IFERROR(IF($J14<>"",G13,""),"") | H14: =IFERROR(IF($J14<>"",H13,""),"") | I14: =IFERROR(IF($J14<>"",I13,""),"") | J14: =IFERROR(IF($B14<>"",J13,""),"") | R14: =IFERROR(IF($J14<>"",R13,""),"") | S14: =IFERROR(IF($J14<>"",S13,""),"") | T14: =IFERROR(IF($J14<>"",T13,""),"") | U14: =IFERROR(IF($J14<>"",U13,""),"") | V14: =IFERROR(IF($J14<>"",V13,""),"") | X14: =IFERROR(VLOOKUP($W14,Plantilla!$B$3:$AE$2497,2,0),"") | Y14: =IFERROR(VLOOKUP($W14,Plantilla!$B$3:$AE$2497,4,0),"") | Z14: =IFERROR(VLOOKUP($W14,Plantilla!$B$3:$AE$2496,4,0),"") | AA14: =IFERROR(VLOOKUP($W14,Plantilla!$B$3:$AJ$2496,17,0),"") | AB14: =IFERROR(IF('(3)_Plan_de_Accion'!M106<>"",'(3)_Plan_de_Accion'!M106,""),"") | AC14: =IFERROR(IF('(3)_Plan_de_Accion'!Q106<>"",'(3)_Plan_de_Accion'!Q106,""),"")
A15: 12 | F15: =IFERROR(IF($J15<>"",F14,""),"") | G15: =IFERROR(IF($J15<>"",G14,""),"") | H15: =IFERROR(IF($J15<>"",H14,""),"") | I15: =IFERROR(IF($J15<>"",I14,""),"") | J15: =IFERROR(IF($B15<>"",J14,""),"") | R15: =IFERROR(IF($J15<>"",R14,""),"") | S15: =IFERROR(IF($J15<>"",S14,""),"") | T15: =IFERROR(IF($J15<>"",T14,""),"") | U15: =IFERROR(IF($J15<>"",U14,""),"") | V15: =IFERROR(IF($J15<>"",V14,""),"") | X15: =IFERROR(VLOOKUP($W15,Plantilla!$B$3:$AE$2497,2,0),"") | Y15: =IFERROR(VLOOKUP($W15,Plantilla!$B$3:$AE$2497,4,0),"") | Z15: =IFERROR(VLOOKUP($W15,Plantilla!$B$3:$AE$2496,4,0),"") | AA15: =IFERROR(VLOOKUP($W15,Plantilla!$B$3:$AJ$2496,17,0),"") | AB15: =IFERROR(IF('(3)_Plan_de_Accion'!M115<>"",'(3)_Plan_de_Accion'!M115,""),"") | AC15: =IFERROR(IF('(3)_Plan_de_Accion'!Q115<>"",'(3)_Plan_de_Accion'!Q115,""),"")
A16: 13 | F16: =IFERROR(IF($J16<>"",F15,""),"") | G16: =IFERROR(IF($J16<>"",G15,""),"") | H16: =IFERROR(IF($J16<>"",H15,""),"") | I16: =IFERROR(IF($J16<>"",I15,""),"") | J16: =IFERROR(IF($B16<>"",J15,""),"") | R16: =IFERROR(IF($J16<>"",R15,""),"") | S16: =IFERROR(IF($J16<>"",S15,""),"") | T16: =IFERROR(IF($J16<>"",T15,""),"") | U16: =IFERROR(IF($J16<>"",U15,""),"") | V16: =IFERROR(IF($J16<>"",V15,""),"") | X16: =IFERROR(VLOOKUP($W16,Plantilla!$B$3:$AE$2497,2,0),"") | Y16: =IFERROR(VLOOKUP($W16,Plantilla!$B$3:$AE$2497,4,0),"") | Z16: =IFERROR(VLOOKUP($W16,Plantilla!$B$3:$AE$2496,4,0),"") | AA16: =IFERROR(VLOOKUP($W16,Plantilla!$B$3:$AJ$2496,17,0),"") | AB16: =IFERROR(IF('(3)_Plan_de_Accion'!M124<>"",'(3)_Plan_de_Accion'!M124,""),"") | AC16: =IFERROR(IF('(3)_Plan_de_Accion'!Q124<>"",'(3)_Plan_de_Accion'!Q124,""),"")
A17: 14 | F17: =IFERROR(IF($J17<>"",F16,""),"") | G17: =IFERROR(IF($J17<>"",G16,""),"") | H17: =IFERROR(IF($J17<>"",H16,""),"") | I17: =IFERROR(IF($J17<>"",I16,""),"") | J17: =IFERROR(IF($B17<>"",J16,""),"") | R17: =IFERROR(IF($J17<>"",R16,""),"") | S17: =IFERROR(IF($J17<>"",S16,""),"") | T17: =IFERROR(IF($J17<>"",T16,""),"") | U17: =IFERROR(IF($J17<>"",U16,""),"") | V17: =IFERROR(IF($J17<>"",V16,""),"") | X17: =IFERROR(VLOOKUP($W17,Plantilla!$B$3:$AE$2497,2,0),"") | Y17: =IFERROR(VLOOKUP($W17,Plantilla!$B$3:$AE$2497,4,0),"") | Z17: =IFERROR(VLOOKUP($W17,Plantilla!$B$3:$AE$2496,4,0),"") | AA17: =IFERROR(VLOOKUP($W17,Plantilla!$B$3:$AJ$2496,17,0),"") | AB17: =IFERROR(IF('(3)_Plan_de_Accion'!M133<>"",'(3)_Plan_de_Accion'!M133,""),"") | AC17: =IFERROR(IF('(3)_Plan_de_Accion'!Q133<>"",'(3)_Plan_de_Accion'!Q133,""),"")
A18: 15 | F18: =IFERROR(IF($J18<>"",F17,""),"") | G18: =IFERROR(IF($J18<>"",G17,""),"") | H18: =IFERROR(IF($J18<>"",H17,""),"") | I18: =IFERROR(IF($J18<>"",I17,""),"") | J18: =IFERROR(IF($B18<>"",J17,""),"") | R18: =IFERROR(IF($J18<>"",R17,""),"") | S18: =IFERROR(IF($J18<>"",S17,""),"") | T18: =IFERROR(IF($J18<>"",T17,""),"") | U18: =IFERROR(IF($J18<>"",U17,""),"") | V18: =IFERROR(IF($J18<>"",V17,""),"") | X18: =IFERROR(VLOOKUP($W18,Plantilla!$B$3:$AE$2497,2,0),"") | Y18: =IFERROR(VLOOKUP($W18,Plantilla!$B$3:$AE$2497,4,0),"") | Z18: =IFERROR(VLOOKUP($W18,Plantilla!$B$3:$AE$2496,4,0),"") | AA18: =IFERROR(VLOOKUP($W18,Plantilla!$B$3:$AJ$2496,17,0),"") | AB18: =IFERROR(IF('(3)_Plan_de_Accion'!M142<>"",'(3)_Plan_de_Accion'!M142,""),"") | AC18: =IFERROR(IF('(3)_Plan_de_Accion'!Q142<>"",'(3)_Plan_de_Accion'!Q142,""),"")
A19: 16 | F19: =IFERROR(IF($J19<>"",F18,""),"") | G19: =IFERROR(IF($J19<>"",G18,""),"") | H19: =IFERROR(IF($J19<>"",H18,""),"") | I19: =IFERROR(IF($J19<>"",I18,""),"") | J19: =IFERROR(IF($B19<>"",J18,""),"") | R19: =IFERROR(IF($J19<>"",R18,""),"") | S19: =IFERROR(IF($J19<>"",S18,""),"") | T19: =IFERROR(IF($J19<>"",T18,""),"") | U19: =IFERROR(IF($J19<>"",U18,""),"") | V19: =IFERROR(IF($J19<>"",V18,""),"") | X19: =IFERROR(VLOOKUP($W19,Plantilla!$B$3:$AE$2497,2,0),"") | Y19: =IFERROR(VLOOKUP($W19,Plantilla!$B$3:$AE$2497,4,0),"") | Z19: =IFERROR(VLOOKUP($W19,Plantilla!$B$3:$AE$2496,4,0),"") | AA19: =IFERROR(VLOOKUP($W19,Plantilla!$B$3:$AJ$2496,17,0),"") | AB19: =IFERROR(IF('(3)_Plan_de_Accion'!M151<>"",'(3)_Plan_de_Accion'!M151,""),"") | AC19: =IFERROR(IF('(3)_Plan_de_Accion'!Q151<>"",'(3)_Plan_de_Accion'!Q151,""),"")
A20: 17 | F20: =IFERROR(IF($J20<>"",F19,""),"") | G20: =IFERROR(IF($J20<>"",G19,""),"") | H20: =IFERROR(IF($J20<>"",H19,""),"") | I20: =IFERROR(IF($J20<>"",I19,""),"") | J20: =IFERROR(IF($B20<>"",J19,""),"") | R20: =IFERROR(IF($J20<>"",R19,""),"") | S20: =IFERROR(IF($J20<>"",S19,""),"") | T20: =IFERROR(IF($J20<>"",T19,""),"") | U20: =IFERROR(IF($J20<>"",U19,""),"") | V20: =IFERROR(IF($J20<>"",V19,""),"") | X20: =IFERROR(VLOOKUP($W20,Plantilla!$B$3:$AE$2497,2,0),"") | Y20: =IFERROR(VLOOKUP($W20,Plantilla!$B$3:$AE$2497,4,0),"") | Z20: =IFERROR(VLOOKUP($W20,Plantilla!$B$3:$AE$2496,4,0),"") | AA20: =IFERROR(VLOOKUP($W20,Plantilla!$B$3:$AJ$2496,17,0),"") | AB20: =IFERROR(IF('(3)_Plan_de_Accion'!M160<>"",'(3)_Plan_de_Accion'!M160,""),"") | AC20: =IFERROR(IF('(3)_Plan_de_Accion'!Q160<>"",'(3)_Plan_de_Accion'!Q160,""),"")
A21: 18 | F21: =IFERROR(IF($J21<>"",F20,""),"") | G21: =IFERROR(IF($J21<>"",G20,""),"") | H21: =IFERROR(IF($J21<>"",H20,""),"") | I21: =IFERROR(IF($J21<>"",I20,""),"") | J21: =IFERROR(IF($B21<>"",J20,""),"") | R21: =IFERROR(IF($J21<>"",R20,""),"") | S21: =IFERROR(IF($J21<>"",S20,""),"") | T21: =IFERROR(IF($J21<>"",T20,""),"") | U21: =IFERROR(IF($J21<>"",U20,""),"") | V21: =IFERROR(IF($J21<>"",V20,""),"") | X21: =IFERROR(VLOOKUP($W21,Plantilla!$B$3:$AE$2497,2,0),"") | Y21: =IFERROR(VLOOKUP($W21,Plantilla!$B$3:$AE$2497,4,0),"") | Z21: =IFERROR(VLOOKUP($W21,Plantilla!$B$3:$AE$2496,4,0),"") | AA21: =IFERROR(VLOOKUP($W21,Plantilla!$B$3:$AJ$2496,17,0),"") | AB21: =IFERROR(IF('(3)_Plan_de_Accion'!M169<>"",'(3)_Plan_de_Accion'!M169,""),"") | AC21: =IFERROR(IF('(3)_Plan_de_Accion'!Q169<>"",'(3)_Plan_de_Accion'!Q169,""),"")
A22: 19 | F22: =IFERROR(IF($J22<>"",F21,""),"") | G22: =IFERROR(IF($J22<>"",G21,""),"") | H22: =IFERROR(IF($J22<>"",H21,""),"") | I22: =IFERROR(IF($J22<>"",I21,""),"") | J22: =IFERROR(IF($B22<>"",J21,""),"") | R22: =IFERROR(IF($J22<>"",R21,""),"") | S22: =IFERROR(IF($J22<>"",S21,""),"") | T22: =IFERROR(IF($J22<>"",T21,""),"") | U22: =IFERROR(IF($J22<>"",U21,""),"") | V22: =IFERROR(IF($J22<>"",V21,""),"") | X22: =IFERROR(VLOOKUP($W22,Plantilla!$B$3:$AE$2497,2,0),"") | Y22: =IFERROR(VLOOKUP($W22,Plantilla!$B$3:$AE$2497,4,0),"") | Z22: =IFERROR(VLOOKUP($W22,Plantilla!$B$3:$AE$2496,4,0),"") | AA22: =IFERROR(VLOOKUP($W22,Plantilla!$B$3:$AJ$2496,17,0),"") | AB22: =IFERROR(IF('(3)_Plan_de_Accion'!M178<>"",'(3)_Plan_de_Accion'!M178,""),"") | AC22: =IFERROR(IF('(3)_Plan_de_Accion'!Q178<>"",'(3)_Plan_de_Accion'!Q178,""),"")
A23: 20 | F23: =IFERROR(IF($J23<>"",F22,""),"") | G23: =IFERROR(IF($J23<>"",G22,""),"") | H23: =IFERROR(IF($J23<>"",H22,""),"") | I23: =IFERROR(IF($J23<>"",I22,""),"") | J23: =IFERROR(IF($B23<>"",J22,""),"") | R23: =IFERROR(IF($J23<>"",R22,""),"") | S23: =IFERROR(IF($J23<>"",S22,""),"") | T23: =IFERROR(IF($J23<>"",T22,""),"") | U23: =IFERROR(IF($J23<>"",U22,""),"") | V23: =IFERROR(IF($J23<>"",V22,""),"") | X23: =IFERROR(VLOOKUP($W23,Plantilla!$B$3:$AE$2497,2,0),"") | Y23: =IFERROR(VLOOKUP($W23,Plantilla!$B$3:$AE$2497,4,0),"") | Z23: =IFERROR(VLOOKUP($W23,Plantilla!$B$3:$AE$2496,4,0),"") | AA23: =IFERROR(VLOOKUP($W23,Plantilla!$B$3:$AJ$2496,17,0),"") | AB23: =IFERROR(IF('(3)_Plan_de_Accion'!M187<>"",'(3)_Plan_de_Accion'!M187,""),"") | AC23: =IFERROR(IF('(3)_Plan_de_Accion'!Q187<>"",'(3)_Plan_de_Accion'!Q187,""),"")
A24: 21 | F24: =IFERROR(IF($J24<>"",F23,""),"") | G24: =IFERROR(IF($J24<>"",G23,""),"") | H24: =IFERROR(IF($J24<>"",H23,""),"") | I24: =IFERROR(IF($J24<>"",I23,""),"") | J24: =IFERROR(IF($B24<>"",J23,""),"") | R24: =IFERROR(IF($J24<>"",R23,""),"") | S24: =IFERROR(IF($J24<>"",S23,""),"") | T24: =IFERROR(IF($J24<>"",T23,""),"") | U24: =IFERROR(IF($J24<>"",U23,""),"") | V24: =IFERROR(IF($J24<>"",V23,""),"") | X24: =IFERROR(VLOOKUP($W24,Plantilla!$B$3:$AE$2497,2,0),"") | Y24: =IFERROR(VLOOKUP($W24,Plantilla!$B$3:$AE$2497,4,0),"") | Z24: =IFERROR(VLOOKUP($W24,Plantilla!$B$3:$AE$2496,4,0),"") | AA24: =IFERROR(VLOOKUP($W24,Plantilla!$B$3:$AJ$2496,17,0),"") | AB24: =IFERROR(IF('(3)_Plan_de_Accion'!M196<>"",'(3)_Plan_de_Accion'!M196,""),"") | AC24: =IFERROR(IF('(3)_Plan_de_Accion'!Q196<>"",'(3)_Plan_de_Accion'!Q196,""),"")
A25: 22 | F25: =IFERROR(IF($J25<>"",F24,""),"") | G25: =IFERROR(IF($J25<>"",G24,""),"") | H25: =IFERROR(IF($J25<>"",H24,""),"") | I25: =IFERROR(IF($J25<>"",I24,""),"") | J25: =IFERROR(IF($B25<>"",J24,""),"") | R25: =IFERROR(IF($J25<>"",R24,""),"") | S25: =IFERROR(IF($J25<>"",S24,""),"") | T25: =IFERROR(IF($J25<>"",T24,""),"") | U25: =IFERROR(IF($J25<>"",U24,""),"") | V25: =IFERROR(IF($J25<>"",V24,""),"") | X25: =IFERROR(VLOOKUP($W25,Plantilla!$B$3:$AE$2497,2,0),"") | Y25: =IFERROR(VLOOKUP($W25,Plantilla!$B$3:$AE$2497,4,0),"") | Z25: =IFERROR(VLOOKUP($W25,Plantilla!$B$3:$AE$2496,4,0),"") | AA25: =IFERROR(VLOOKUP($W25,Plantilla!$B$3:$AJ$2496,17,0),"") | AB25: =IFERROR(IF('(3)_Plan_de_Accion'!M205<>"",'(3)_Plan_de_Accion'!M205,""),"") | AC25: =IFERROR(IF('(3)_Plan_de_Accion'!Q205<>"",'(3)_Plan_de_Accion'!Q205,""),"")
A26: 23 | F26: =IFERROR(IF($J26<>"",F25,""),"") | G26: =IFERROR(IF($J26<>"",G25,""),"") | H26: =IFERROR(IF($J26<>"",H25,""),"") | I26: =IFERROR(IF($J26<>"",I25,""),"") | J26: =IFERROR(IF($B26<>"",J25,""),"") | R26: =IFERROR(IF($J26<>"",R25,""),"") | S26: =IFERROR(IF($J26<>"",S25,""),"") | T26: =IFERROR(IF($J26<>"",T25,""),"") | U26: =IFERROR(IF($J26<>"",U25,""),"") | V26: =IFERROR(IF($J26<>"",V25,""),"") | X26: =IFERROR(VLOOKUP($W26,Plantilla!$B$3:$AE$2497,2,0),"") | Y26: =IFERROR(VLOOKUP($W26,Plantilla!$B$3:$AE$2497,4,0),"") | Z26: =IFERROR(VLOOKUP($W26,Plantilla!$B$3:$AE$2496,4,0),"") | AA26: =IFERROR(VLOOKUP($W26,Plantilla!$B$3:$AJ$2496,17,0),"") | AB26: =IFERROR(IF('(3)_Plan_de_Accion'!M214<>"",'(3)_Plan_de_Accion'!M214,""),"") | AC26: =IFERROR(IF('(3)_Plan_de_Accion'!Q214<>"",'(3)_Plan_de_Accion'!Q214,""),"")
A27: 24 | F27: =IFERROR(IF($J27<>"",F26,""),"") | G27: =IFERROR(IF($J27<>"",G26,""),"") | H27: =IFERROR(IF($J27<>"",H26,""),"") | I27: =IFERROR(IF($J27<>"",I26,""),"") | J27: =IFERROR(IF($B27<>"",J26,""),"") | R27: =IFERROR(IF($J27<>"",R26,""),"") | S27: =IFERROR(IF($J27<>"",S26,""),"") | T27: =IFERROR(IF($J27<>"",T26,""),"") | U27: =IFERROR(IF($J27<>"",U26,""),"") | V27: =IFERROR(IF($J27<>"",V26,""),"") | X27: =IFERROR(VLOOKUP($W27,Plantilla!$B$3:$AE$2497,2,0),"") | Y27: =IFERROR(VLOOKUP($W27,Plantilla!$B$3:$AE$2497,4,0),"") | Z27: =IFERROR(VLOOKUP($W27,Plantilla!$B$3:$AE$2496,4,0),"") | AA27: =IFERROR(VLOOKUP($W27,Plantilla!$B$3:$AJ$2496,17,0),"") | AB27: =IFERROR(IF('(3)_Plan_de_Accion'!M223<>"",'(3)_Plan_de_Accion'!M223,""),"") | AC27: =IFERROR(IF('(3)_Plan_de_Accion'!Q223<>"",'(3)_Plan_de_Accion'!Q223,""),"")
A28: 25 | F28: =IFERROR(IF($J28<>"",F27,""),"") | G28: =IFERROR(IF($J28<>"",G27,""),"") | H28: =IFERROR(IF($J28<>"",H27,""),"") | I28: =IFERROR(IF($J28<>"",I27,""),"") | J28: =IFERROR(IF($B28<>"",J27,""),"") | R28: =IFERROR(IF($J28<>"",R27,""),"") | S28: =IFERROR(IF($J28<>"",S27,""),"") | T28: =IFERROR(IF($J28<>"",T27,""),"") | U28: =IFERROR(IF($J28<>"",U27,""),"") | V28: =IFERROR(IF($J28<>"",V27,""),"") | X28: =IFERROR(VLOOKUP($W28,Plantilla!$B$3:$AE$2497,2,0),"") | Y28: =IFERROR(VLOOKUP($W28,Plantilla!$B$3:$AE$2497,4,0),"") | Z28: =IFERROR(VLOOKUP($W28,Plantilla!$B$3:$AE$2496,4,0),"") | AA28: =IFERROR(VLOOKUP($W28,Plantilla!$B$3:$AJ$2496,17,0),"") | AB28: =IFERROR(IF('(3)_Plan_de_Accion'!M232<>"",'(3)_Plan_de_Accion'!M232,""),"") | AC28: =IFERROR(IF('(3)_Plan_de_Accion'!Q232<>"",'(3)_Plan_de_Accion'!Q232,""),"")
A29: 26 | F29: =IFERROR(IF($J29<>"",F28,""),"") | G29: =IFERROR(IF($J29<>"",G28,""),"") | H29: =IFERROR(IF($J29<>"",H28,""),"") | I29: =IFERROR(IF($J29<>"",I28,""),"") | J29: =IFERROR(IF($B29<>"",J28,""),"") | R29: =IFERROR(IF($J29<>"",R28,""),"") | S29: =IFERROR(IF($J29<>"",S28,""),"") | T29: =IFERROR(IF($J29<>"",T28,""),"") | U29: =IFERROR(IF($J29<>"",U28,""),"") | V29: =IFERROR(IF($J29<>"",V28,""),"") | X29: =IFERROR(VLOOKUP($W29,Plantilla!$B$3:$AE$2497,2,0),"") | Y29: =IFERROR(VLOOKUP($W29,Plantilla!$B$3:$AE$2497,4,0),"") | Z29: =IFERROR(VLOOKUP($W29,Plantilla!$B$3:$AE$2496,4,0),"") | AA29: =IFERROR(VLOOKUP($W29,Plantilla!$B$3:$AJ$2496,17,0),"") | AB29: =IFERROR(IF('(3)_Plan_de_Accion'!M241<>"",'(3)_Plan_de_Accion'!M241,""),"") | AC29: =IFERROR(IF('(3)_Plan_de_Accion'!Q241<>"",'(3)_Plan_de_Accion'!Q241,""),"")
A30: 27 | F30: =IFERROR(IF($J30<>"",F29,""),"") | G30: =IFERROR(IF($J30<>"",G29,""),"") | H30: =IFERROR(IF($J30<>"",H29,""),"") | I30: =IFERROR(IF($J30<>"",I29,""),"") | J30: =IFERROR(IF($B30<>"",J29,""),"") | R30: =IFERROR(IF($J30<>"",R29,""),"") | S30: =IFERROR(IF($J30<>"",S29,""),"") | T30: =IFERROR(IF($J30<>"",T29,""),"") | U30: =IFERROR(IF($J30<>"",U29,""),"") | V30: =IFERROR(IF($J30<>"",V29,""),"") | X30: =IFERROR(VLOOKUP($W30,Plantilla!$B$3:$AE$2497,2,0),"") | Y30: =IFERROR(VLOOKUP($W30,Plantilla!$B$3:$AE$2497,4,0),"") | Z30: =IFERROR(VLOOKUP($W30,Plantilla!$B$3:$AE$2496,4,0),"") | AA30: =IFERROR(VLOOKUP($W30,Plantilla!$B$3:$AJ$2496,17,0),"") | AB30: =IFERROR(IF('(3)_Plan_de_Accion'!M250<>"",'(3)_Plan_de_Accion'!M250,""),"") | AC30: =IFERROR(IF('(3)_Plan_de_Accion'!Q250<>"",'(3)_Plan_de_Accion'!Q250,""),"")
A31: 28 | F31: =IFERROR(IF($J31<>"",F30,""),"") | G31: =IFERROR(IF($J31<>"",G30,""),"") | H31: =IFERROR(IF($J31<>"",H30,""),"") | I31: =IFERROR(IF($J31<>"",I30,""),"") | J31: =IFERROR(IF($B31<>"",J30,""),"") | R31: =IFERROR(IF($J31<>"",R30,""),"") | S31: =IFERROR(IF($J31<>"",S30,""),"") | T31: =IFERROR(IF($J31<>"",T30,""),"") | U31: =IFERROR(IF($J31<>"",U30,""),"") | V31: =IFERROR(IF($J31<>"",V30,""),"") | X31: =IFERROR(VLOOKUP($W31,Plantilla!$B$3:$AE$2497,2,0),"") | Y31: =IFERROR(VLOOKUP($W31,Plantilla!$B$3:$AE$2497,4,0),"") | Z31: =IFERROR(VLOOKUP($W31,Plantilla!$B$3:$AE$2496,4,0),"") | AA31: =IFERROR(VLOOKUP($W31,Plantilla!$B$3:$AJ$2496,17,0),"") | AB31: =IFERROR(IF('(3)_Plan_de_Accion'!M259<>"",'(3)_Plan_de_Accion'!M259,""),"") | AC31: =IFERROR(IF('(3)_Plan_de_Accion'!Q259<>"",'(3)_Plan_de_Accion'!Q259,""),"")
A32: 29 | F32: =IFERROR(IF($J32<>"",F31,""),"") | G32: =IFERROR(IF($J32<>"",G31,""),"") | H32: =IFERROR(IF($J32<>"",H31,""),"") | I32: =IFERROR(IF($J32<>"",I31,""),"") | J32: =IFERROR(IF($B32<>"",J31,""),"") | R32: =IFERROR(IF($J32<>"",R31,""),"") | S32: =IFERROR(IF($J32<>"",S31,""),"") | T32: =IFERROR(IF($J32<>"",T31,""),"") | U32: =IFERROR(IF($J32<>"",U31,""),"") | V32: =IFERROR(IF($J32<>"",V31,""),"") | X32: =IFERROR(VLOOKUP($W32,Plantilla!$B$3:$AE$2497,2,0),"") | Y32: =IFERROR(VLOOKUP($W32,Plantilla!$B$3:$AE$2497,4,0),"") | Z32: =IFERROR(VLOOKUP($W32,Plantilla!$B$3:$AE$2496,4,0),"") | AA32: =IFERROR(VLOOKUP($W32,Plantilla!$B$3:$AJ$2496,17,0),"") | AB32: =IFERROR(IF('(3)_Plan_de_Accion'!M268<>"",'(3)_Plan_de_Accion'!M268,""),"") | AC32: =IFERROR(IF('(3)_Plan_de_Accion'!Q268<>"",'(3)_Plan_de_Accion'!Q268,""),"")
A33: 30 | F33: =IFERROR(IF($J33<>"",F32,""),"") | G33: =IFERROR(IF($J33<>"",G32,""),"") | H33: =IFERROR(IF($J33<>"",H32,""),"") | I33: =IFERROR(IF($J33<>"",I32,""),"") | J33: =IFERROR(IF($B33<>"",J32,""),"") | R33: =IFERROR(IF($J33<>"",R32,""),"") | S33: =IFERROR(IF($J33<>"",S32,""),"") | T33: =IFERROR(IF($J33<>"",T32,""),"") | U33: =IFERROR(IF($J33<>"",U32,""),"") | V33: =IFERROR(IF($J33<>"",V32,""),"") | X33: =IFERROR(VLOOKUP($W33,Plantilla!$B$3:$AE$2497,2,0),"") | Y33: =IFERROR(VLOOKUP($W33,Plantilla!$B$3:$AE$2497,4,0),"") | Z33: =IFERROR(VLOOKUP($W33,Plantilla!$B$3:$AE$2496,4,0),"") | AA33: =IFERROR(VLOOKUP($W33,Plantilla!$B$3:$AJ$2496,17,0),"") | AB33: =IFERROR(IF('(3)_Plan_de_Accion'!M277<>"",'(3)_Plan_de_Accion'!M277,""),"") | AC33: =IFERROR(IF('(3)_Plan_de_Accion'!Q277<>"",'(3)_Plan_de_Accion'!Q277,""),"")

Sheet (3)_Plan_de_Accion
F2: PLAN DE ACCIÓN CORRECTIVA PARA ATENDER LOS HALLAZGOS Y RECOMENDACIONES
B5: Empresa | E5: Banco Base | G5: a | H5: Arrendadora Base | K5: Casa de Bolsa Base | N5: GFBASE
AF6: ACEPTABLE | AI6: ANTONIO FLORES LUNA | AJ6: Director de Auditoría Interna
A7: Cifras al | C7: =IFERROR(IF('(1)_Base_de_Datos'!I4<>"",'(1)_Base_de_Datos'!I4,""),"") | G7: Periodo de Revisión: | J7: =IFERROR(IF('(1)_Base_de_Datos'!H4<>"",'(1)_Base_de_Datos'!H4,""),"") | Q7: Fecha de elaboración | R7: =IFERROR(IF('(1)_Base_de_Datos'!V4<>"",'(1)_Base_de_Datos'!V4,""),"") | U7: EN CASO DE REALIZAR COMENTARIOS ADICIONALES, COMO OBJETIVOS, CARACTERÍSTICAS, ETC., MOSTRAR LAS CELDAS 10 A LA 15 QUE ESTÁN OCULTAS. | AF7: PARCIALMENTE ACEPTABLE | AI7: CARLOS ALBERTO NAVARRO RIVERA | AJ7: Subdirección de Auditoría Procesos de Staff y Riesgos
G8: =IF(J8<>"","Proceso Auditado", "") | J8: =IFERROR(IF('(1)_Base_de_Datos'!J4<>"",'(1)_Base_de_Datos'!J4,""),"") | AF8: INACEPTABLE
G9: =IF(J9<>"","Nombre del Monitoreo", "") | J9: =IFERROR(IF('(1)_Base_de_Datos'!K4<>"",'(1)_Base_de_Datos'!K4,""),"") | P9: Auditor | Q9: =IFERROR(IF('(1)_Base_de_Datos'!T4<>"",'(1)_Base_de_Datos'!T4,""),"") | AF9: Resultado2
A11: A U D I T O R Í A | M11: Á R E A A U D I T A D A
A12: No. | B12: HALLAZGO | G12: GRADO DE RIESGO | H12: IMPLICACIÓN/ FUNDAMENTO | L12: TIPO DE HALLAZGO | M12: COMPROMISO | Q12: FECHA COMPROMISO | R12: RESPONSABLE | S12: PUESTO RESPONSABLE
B13: =IF('(1)_Base_de_Datos'!$R$4<>"",'(1)_Base_de_Datos'!$R$4,"") | H13: =IF('(1)_Base_de_Datos'!$B$4="Recomendación",'(1)_Base_de_Datos'!$B$4,"")
A14: 1 | B14: =IFERROR(IF('(1)_Base_de_Datos'!L4<>"",'(1)_Base_de_Datos'!L4,""),"") | G14: =IFERROR(IF('(1)_Base_de_Datos'!C4<>"",'(1)_Base_de_Datos'!C4,""),"") | H14: IMPLICACIÓN | L14: =IFERROR(IF('(1)_Base_de_Datos'!Q4<>"",'(1)_Base_de_Datos'!Q4,""),"") | M14: Se corregirá la clasificación sectorial identificada y el cálculo de la exposición y reserva; adicionalmente, se reforzarán las validaciones previas al cierre para asegurar la correcta determinación de PI, SP y reservas. | R14: =IFERROR(IF('(1)_Base_de_Datos'!X4<>"",'(1)_Base_de_Datos'!X4,""),"") | S14: =IFERROR(IF('(1)_Base_de_Datos'!Y4<>"",'(1)_Base_de_Datos'!Y4,""),"")
B15: =IFERROR(IF('(1)_Base_de_Datos'!M4<>"",'(1)_Base_de_Datos'!M4,""),"") | H15: =IFERROR(IF('(1)_Base_de_Datos'!N4<>"",'(1)_Base_de_Datos'!N4,""),"")
H17: FUNDAMENTO
H18: =IFERROR(IF('(1)_Base_de_Datos'!O4<>"",'(1)_Base_de_Datos'!O4,""),"")
H20: CONTROL
H21: =IFERROR(IF('(1)_Base_de_Datos'!P4<>"",'(1)_Base_de_Datos'!P4,""),"")
B22: =IF('(1)_Base_de_Datos'!$R$5<>"",'(1)_Base_de_Datos'!$R$5,"") | H22: =IF('(1)_Base_de_Datos'!$B$5="Recomendación",'(1)_Base_de_Datos'!$B$5,"")
A23: 2 | B23: =IFERROR(IF('(1)_Base_de_Datos'!L5<>"",'(1)_Base_de_Datos'!L5,""),"") | G23: =IFERROR(IF('(1)_Base_de_Datos'!C5<>"",'(1)_Base_de_Datos'!C5,""),"") | H23: IMPLICACIÓN | L23: =IFERROR(IF('(1)_Base_de_Datos'!Q5<>"",'(1)_Base_de_Datos'!Q5,""),"") | M23: Se corregirá el valor reportado en el campo 45 del R04-C-0438 conforme al instructivo vigente y se incorporará una validación previa al envío para asegurar la calidad de la información regulatoria. | R23: =IFERROR(IF('(1)_Base_de_Datos'!X5<>"",'(1)_Base_de_Datos'!X5,""),"") | S23: =IFERROR(IF('(1)_Base_de_Datos'!Y5<>"",'(1)_Base_de_Datos'!Y5,""),"")
B24: =IFERROR(IF('(1)_Base_de_Datos'!M5<>"",'(1)_Base_de_Datos'!M5,""),"") | H24: =IFERROR(IF('(1)_Base_de_Datos'!N5<>"",'(1)_Base_de_Datos'!N5,""),"")
H26: FUNDAMENTO
H27: =IFERROR(IF('(1)_Base_de_Datos'!O5<>"",'(1)_Base_de_Datos'!O5,""),"")
H29: CONTROL
H30: =IFERROR(IF('(1)_Base_de_Datos'!P5<>"",'(1)_Base_de_Datos'!P5,""),"")
B31: =IF('(1)_Base_de_Datos'!$R$6<>"",'(1)_Base_de_Datos'!$R$6,"") | H31: =IF('(1)_Base_de_Datos'!$B$6="Recomendación",'(1)_Base_de_Datos'!$B$6,"")
A32: 3 | B32: =IFERROR(IF('(1)_Base_de_Datos'!L6<>"",'(1)_Base_de_Datos'!L6,""),"") | G32: =IFERROR(IF('(1)_Base_de_Datos'!C6<>"",'(1)_Base_de_Datos'!C6,""),"") | H32: IMPLICACIÓN | L32: =IFERROR(IF('(1)_Base_de_Datos'!Q6<>"",'(1)_Base_de_Datos'!Q6,""),"") | R32: =IFERROR(IF('(1)_Base_de_Datos'!X6<>"",'(1)_Base_de_Datos'!X6,""),"") | S32: =IFERROR(IF('(1)_Base_de_Datos'!Y6<>"",'(1)_Base_de_Datos'!Y6,""),"")
B33: =IFERROR(IF('(1)_Base_de_Datos'!M6<>"",'(1)_Base_de_Datos'!M6,""),"") | H33: =IFERROR(IF('(1)_Base_de_Datos'!N6<>"",'(1)_Base_de_Datos'!N6,""),"")
H35: FUNDAMENTO
H36: =IFERROR(IF('(1)_Base_de_Datos'!O6<>"",'(1)_Base_de_Datos'!O6,""),"")
H38: CONTROL
H39: =IFERROR(IF('(1)_Base_de_Datos'!P6<>"",'(1)_Base_de_Datos'!P6,""),"")
B40: =IF('(1)_Base_de_Datos'!$R$7<>"",'(1)_Base_de_Datos'!$R$7,"") | H40: =IF('(1)_Base_de_Datos'!$B$7="Recomendación",'(1)_Base_de_Datos'!$B$7,"")
A41: 4 | B41: =IFERROR(IF('(1)_Base_de_Datos'!L7<>"",'(1)_Base_de_Datos'!L7,""),"") | G41: =IFERROR(IF('(1)_Base_de_Datos'!C7<>"",'(1)_Base_de_Datos'!C7,""),"") | H41: IMPLICACIÓN | L41: =IFERROR(IF('(1)_Base_de_Datos'!Q7<>"",'(1)_Base_de_Datos'!Q7,""),"") | R41: =IFERROR(IF('(1)_Base_de_Datos'!X7<>"",'(1)_Base_de_Datos'!X7,""),"") | S41: =IFERROR(IF('(1)_Base_de_Datos'!Y7<>"",'(1)_Base_de_Datos'!Y7,""),"")
B42: =IFERROR(IF('(1)_Base_de_Datos'!M7<>"",'(1)_Base_de_Datos'!M7,""),"") | H42: =IFERROR(IF('(1)_Base_de_Datos'!N7<>"",'(1)_Base_de_Datos'!N7,""),"")
H44: FUNDAMENTO
H45: =IFERROR(IF('(1)_Base_de_Datos'!O7>"",'(1)_Base_de_Datos'!O7,""),"")
H47: CONTROL
H48: =IFERROR(IF('(1)_Base_de_Datos'!P7<>"",'(1)_Base_de_Datos'!P7,""),"")
B49: =IF('(1)_Base_de_Datos'!$R$8<>"",'(1)_Base_de_Datos'!$R$8,"") | H49: =IF('(1)_Base_de_Datos'!$B$8="Recomendación",'(1)_Base_de_Datos'!$B$8,"")
A50: 5 | B50: =IFERROR(IF('(1)_Base_de_Datos'!L8<>"",'(1)_Base_de_Datos'!L8,""),"") | G50: =IFERROR(IF('(1)_Base_de_Datos'!C8<>"",'(1)_Base_de_Datos'!C8,""),"") | H50: IMPLICACIÓN | L50: =IFERROR(IF('(1)_Base_de_Datos'!Q8<>"",'(1)_Base_de_Datos'!Q8,""),"") | R50: =IFERROR(IF('(1)_Base_de_Datos'!X8<>"",'(1)_Base_de_Datos'!X8,""),"") | S50: =IFERROR(IF('(1)_Base_de_Datos'!Y8<>"",'(1)_Base_de_Datos'!Y8,""),"")
B51: =IFERROR(IF('(1)_Base_de_Datos'!M8<>"",'(1)_Base_de_Datos'!M8,""),"") | H51: =IFERROR(IF('(1)_Base_de_Datos'!N8<>"",'(1)_Base_de_Datos'!N8,""),"")
H53: FUNDAMENTO
...

Sheet Acerno_Cache_XXXXX

Sheet datos
L1: PLAN ANUAL 2025
B2: EMPRESA | D2: OBSERVACION / RECOMENDACIÓN | F2: No | G2: Riesgo | H2: Concepto | J2: CLASIFICACIÓN DE PROCESO AUDITADO | L2: NOMBRE DE LA AUDITORIA | N2: NOMBRE DEL MONITOREO | P2: CONTROL INTERNO | R2: TIPO DE HALLAZGO | T2: DEPTO DE AUDITORÍA INTERNA | V2: DEPTO DE AUDITORÍA INTERNA | W2: AUDITOR RESPONSABLE | X2: Puesto | Y2: Area del Auditor
B3: Banco BASE | D3: Observación | F3: 1 | G3: BAJO | H3: a) Observaciones sobre Actualizaciones e incumplimiento a la Normatividad Interna b) Desviaciones menores por falta de capacitación C) Inexistencia total de normatividad en procesos o actividades identificadas y realizadas por las áreas | J3: Control | L3: 31 PUNTOS BANXICO OPERACIONES DERIVADAS, MARIZ | N3: No Aplica | P3: Ausencia de Control | R3: Actualización a la Normatividad | T3: Auditoría de Tesorería y Mercados | V3: Auditoría de Tesorería y Mercados | W3: Alejandro Guadalupe Solis Arteaga | X3: Auditor Jr | Y3: TYM
B4: Casa de Bolsa BASE | D4: Recomendación | F4: 2 | G4: BAJO (Reincidente) | H4: a) Observaciones sobre Actualizaciones e incumplimiento a la Normatividad Interna b) Desviaciones menores por falta de capacitación C) Inexistencia total de normatividad en procesos o actividades identificadas y realizadas por las áreas | J4: Soporte | L4: 31 PUNTOS DE DERIVADOS | N4: Acuses de entrega de Tokens | P4: Deficiencia del diseño del control | R4: Ausencia de Normatividad | T4: Auditoría de Riesgos y Perfiles | V4: Auditoría de Riesgos y Perfiles | W4: Angela Michelle López Muñiz | X4: Auditor Jr | Y4: RYP
B5: Grupo Financiero BASE | F5: 3 | G5: MEDIO | H5: a) Observaciones relacionadas con fallas en la ejecución de Controles del proceso, sin afectaciones económicas b) Observaciones sobre Normatividad no existente o desactualizada relacionada con temas Regulatorios C) Observaciones reincidencia | J5: Negocio | L5: 31 PUNTOS DERIVADOS, MODELOS DE VALUACIÓN | N5: Actualización de atributos de garantías hipotecarias y prendarias | P5: Falla en la ejecución del control | R5: Desarrollo Tecnológico | T5: Auditoría de Operaciones Pasivas y Tecnología | V5: Auditoría de Crédito Empresarial | W5: Blanca Nelly Gutiérrez Garza | X5: Auditor Sr | Y5: CRE
F6: 4 | G6: MEDIO (Reincidente) | H6: a) Observaciones relacionadas con fallas en la ejecución de Controles del proceso, sin afectaciones económicas b) Observaciones sobre Normatividad no existente o desactualizada relacionada con temas Regulatorios C) Observaciones reincidencia | L6: ACREEDORES SALDOS NUBA | N6: Cartas de Autorización de Reporte de Buró de Crédito | R6: Diseño del Control Limitado | T6: Auditoría de Crédito Empresarial | V6: Auditoría de Operaciones Pasivas y Tecnología | W6: Brenda Nairobi Santiago Morales | X6: Auditor Jr | Y6: OPT
F7: 5 | G7: ALTO | H7: a) Observaciones sobre el incumplimientos de Controles Operativos Clave y/o Controles Automáticos sin afectaciones económicas a la Institución o cliente (No se ha materializado el Fraudes, Desviaciones o Fallas Graves de Controles, Quebrantos, etc.) b) Observaciones sobre incumplimientos regulatorios (Total o Parcial), sin antecedente de sanción aplicada a la Institución c) Observaciones relacionadas con fallas en la ejecución de Controles del proceso, con impacto económico para la Institución. d) Observaciones reincidentes | L7: ADMINISTRACION INTEGRAL DE RIESGOS (MERCADO LIQUIDEZ, CRÉDITO, OPERACIONAL) | N7: Concertación de Títulos de Terceros | R7: Falta de Capacitación | T7: Auditoría de Administración, Contabilidad y Finanzas. | V7: Auditoría de Operaciones Pasivas y Tecnología | W7: Cinthia Vianey Muro Casas | X7: Auditor Sr | Y7: OPT
F8: 6 | G8: ALTO (Reincidente) | H8: a) Observaciones sobre el incumplimientos de Controles Operativos Clave y/o Controles Automáticos sin afectaciones económicas a la Institución o cliente (No se ha materializado el Fraudes, Desviaciones o Fallas Graves de Controles, Quebrantos, etc.) b) Observaciones sobre incumplimientos regulatorios (Total o Parcial), sin antecedente de sanción aplicada a la Institución c) Observaciones relacionadas con fallas en la ejecución de Controles del proceso, con impacto económico para la Institución. d) Observaciones reincidentes | L8: ADMINISTRACIÓN Y ASIGNACIÓN DE TOKEN | N8: Confirmación de Operaciones de Productos Financieros Derivados | R8: Falta de Ejecución en el Control | V8: Auditoría de Tesorería y Mercados | W8: Diana Patricia Mosqueda Peña | X8: Auditor Jr | Y8: TYM
F9: 7 | G9: MUY ALTO | H9: a) Observaciones sobre los incumplimientos de Controles Operativos Clave y/o Controles Automáticos con afectaciones económicas a la Institución o al cliente (Fraudes, Desviaciones o Fallas Graves de Controles, Quebrantos, etc.). b) Observaciones sobre incumplimientos regulatorios (Total o Parcial), con antecedente de sanción aplicada a la Institución. c) Observaciones originadas por malas practicas que se materializaron en un riesgo a la Institución y/o clientes. d) Observaciones reincidentes cuya materialización haya tenido como consecuencia un impactado de Fraude y/o Quebranto. | L9: ALTA DESTINATARIOS | N9: Contratos Márgenes Únicos | R9: Inexistencia de Control | V9: Auditoría de Tesorería y Mercados | W9: Domingo José Palermo Rodríguez | X9: Subdirector de Auditoría | Y9: TYM
F10: 8 | G10: MUY ALTO (Reincidente) | H10: a) Observaciones sobre los incumplimientos de Controles Operativos Clave y/o Controles Automáticos con afectaciones económicas a la Institución o al cliente (Fraudes, Desviaciones o Fallas Graves de Controles, Quebrantos, etc.). b) Observaciones sobre incumplimientos regulatorios (Total o Parcial), con antecedente de sanción aplicada a la Institución. c) Observaciones originadas por malas practicas que se materializaron en un riesgo a la Institución y/o clientes. d) Observaciones reincidentes cuya materialización haya tenido como consecuencia un impactado de Fraude y/o Quebranto. | L10: ALTAS, BAJAS Y CAMBIOS DE USUARIOS | N10: Cuentas de Clientes con depósitos de Colaboradores | R10: Incumplimiento Regulatorio | V10: Auditoría de Riesgos y Perfiles | W10: Elias Escobedo García | X10: Auditor Sr | Y10: RYP
L11: APLICACIONES DE NEGOCIO | N11: Cuestionario de Gobierno Corporativo | V11: Auditoría de Riesgos y Perfiles | W11: Erick Alberto Merinos García | X11: Auditor Sr | Y11: RYP
L12: ARQUEOS DE CAJA | N12: Custodia de Documentos Originales de Captación | V12: Auditoría de Crédito Empresarial | W12: Evelyn Natividad Gochar Calderón | X12: Auditor Jr | Y12: CRE
L13: ARRENDAMIENTO MEXICO | N13: Diario de Revelación del CCL | V13: Auditoría de Riesgos y Perfiles | W13: Evelyn Yamileth Martínez Galván | X13: Auditor Jr | Y13: RYP
L14: ARRENDAMIENTO MONTERREY | N14: Efectivo en cajas al final del día | V14: Auditoría de Operaciones Pasivas y Tecnología | W14: Fernando Huerta López | X14: Gerente de Auditoría | Y14: OPT
L15: AUDITORIA LEGAL | N15: Eliminación de Cuentas de Usuarios en el Directorio Activo | V15: Auditoría de Operaciones Pasivas y Tecnología | W15: Griselda Torres Martínez | X15: Auditor Sr | Y15: OPT
L16: BANCA ELECTRONICA | N16: Empleados en periodos de inactividad vacaciones o incapacidades | V16: Auditoría de Tesorería y Mercados | W16: Jorge Alberto Maldonado Cantú | X16: Auditor Sr | Y16: TYM
L17: BIENES ADJUNDICADOS | N17: Liquidación de Operaciones en cuentas autorizadas de contratos de Mercado de Dinero | V17: Auditoría de Operaciones Pasivas y Tecnología | W17: Jorge Ugarte Muro | X17: Auditor Sr | Y17: OPT
L18: BIOMETRICOS Y ROBO DE IDENTIDAD | N18: Liquidación de Operaciones en cuentas autorizadas de contratos de Mercado de Dinero, Capitales y Fondos de Inversión | V18: Auditoría de Riesgos y Perfiles | W18: José Enrique Duque Leal | X18: Gerente de Auditoría | Y18: RYP
L19: BLOQUEO Y RESTRICCIÓN CLIENTES POR OFICIOS | N19: Mensual Cuotas IPAB | V19: Auditoría de Operaciones Pasivas y Tecnología | W19: Julio Manuel Flores Treviño | X19: Auditor Sr | Y19: OPT
L20: BURO DE CREDITO - ADMINISTRACIÓN EXPEDIENTES | N20: Págares (Banco y Arrendadora) | V20: Auditoría de Operaciones Pasivas y Tecnología | W20: Oscar Montelongo Vázquez | X20: Auditor Sr | Y20: OPT
L21: BURÓ DE CRÉDITO - REPORTE A BURÓ DE CRÉDITO | N21: Pólizas Manuales | V21: Auditoría de Crédito Empresarial | W21: Rafael Pacheco Torres | X21: Gerente de Auditoría | Y21: CRE
L22: CAJAS OPERATIVAS Y OPERACIONES EN EFECTIVO | N22: Recalificación de Líneas de Crédito | V22: Auditoría de Operaciones Pasivas y Tecnología | W22: Samantha Kahori Cobarrubias Ubaldo | X22: Analista Auditoría TI | Y22: OPT
L23: CALIDAD DE INFORMACIÓN DE CLIENTES | N23: Recalificación de Líneas de Derivados | V23: Auditoría de Riesgos y Perfiles | W23: Yarelli Michell Cruz Sánchez | X23: Auditor Jr | Y23: RYP
L24: CALIFICACION DE CARTERA | N24: Retiro de Efectivo Empleados
L25: CAMBIOS | N25: Segregación de funciones
L26: CARTAS DE CRÉDITO | N26: Solicitudes de Financiamiento, Visitas Oculares, Avalúos y Pólizas de Seguro
L27: CCL - CFEN | N27: Validación de datos de proveedores de la Institución (Minería de Datos)
L28: CENTRO DE ACLARACION Y SERVICIO CAS | N28: Validación de listado de proveedores críticos con base en los Anexos 69 y 69B del CFF
L29: CERTIFICA CIONES CNBV USO HERRAMIENTAS INFORMÁTICAS PREV DE FRAUDES | N29: Verificación de Reportes de Aclaraciones, Consultas y Reclamaciones en UNE
L30: CERTIFICACIÓN ANUAL CUOTAS IPAB
L31: CERTIFICACION PARTES RELACIONADAS
L32: CERTIFICACION REPORTES REGULATORIOS
L33: CERTIFICACIÓN SPEI Externo
L34: CERTIFICACIÓN SWIFT
L35: CERTIFICACIONES CNBV CONTRASEÑAS Bca x Int Web y Movil
L36: CERTIFICACIONES CNBV NOTIFICACIONES Art 51
L37: CERTIFICACIONES CNBV SOFT TOKEN
L38: CERTIFICACIONES CNBV TIEMPOS ESPERA TRANSF. TERCEROS BASEINET
L39: CFEN
L40: CHEQUERA DIGITAL - CAPTACIÓN A LA VISTA
...

Sheet Plantilla
A2: INFORMACION AGOSTO 2026
B3: 1 | C3: 2 | D3: 3 | E3: 4 | F3: 5 | G3: 6 | H3: 7 | I3: 8 | J3: 9 | K3: 10 | L3: 11 | M3: 12 | N3: 13 | O3: 14 | P3: 15 | Q3: 16 | R3: 17 | S3: 18 | T3: 19 | U3: 20 | V3: 21 | W3: 22 | X3: 23 | Y3: 24 | Z3: 25 | AA3: 26 | AB3: 27 | AC3: 28 | AD3: 29 | AE3: 30 | AF3: 31 | AG3: 32 | AH3: 33 | AI3: 34 | AJ3: 35
A4: USUARIO | B4: NIP | C4: NOMBRE | D4: CODIGO POSICION | E4: POSICION | F4: ATRIBUTO SUCURSAL | G4: NIP DEL JEFE | H4: NOMBRE DEL JEFE | I4: CODIGO POSICION DEL JEFE | J4: POSICION DEL JEFE | K4: ID ELEMENTO EMPRESA | L4: DESCRIPCION EMPRESA | M4: ID ELEMENTO DIRECCION GENERAL | N4: DESCRIPCION DIRECCION GENERAL | O4: ID ELEMENTO DIRECCION | P4: DESCRIPCION DIRECCION | Q4: ID ELEMENTO AREA | R4: DESCRIPCION AREA | S4: ID ELEMENTO GERENCIA | T4: DESCRIPCION GERENCIA | U4: ID ELEMENTO DEPARTAMENTO CC | V4: DESCRIPCION DEPARTAMENTO CC | W4: ID ELEMENTO CENTRO DE RESP | X4: DESCRIPCION CENTRO DE RESP | Y4: CLAVE ETIQUETA 1 | Z4: DESCRIPCION ETIQUETA 1 | AA4: CLAVE ETIQUETA 2 | AB4: DESCRIPCION ETIQUETA 2 | AC4: CLAVE ETIQUETA 3 | AD4: DESCRIPCION ETIQUETA 3 | AE4: CLAVE ETIQUETA 4 | AF4: DESCRIPCION ETIQUETA 4 | AG4: ID ELEMENTO PLAZA | AH4: DESCRIPCION PLAZA | AI4: Correo Electrónico | AJ4: Fecha Ingreso
A5: LBARRERA | B5: 1 | C5: LORENZO BARRERA SEGOVIA | D5: 1 | E5: PRESIDENTE EJECUTIVO | F5: MONTERREY | K5: 1 | L5: PRESIDENCIA EJECUTIVA DEL CONSEJO | M5: 10 | N5: PRESIDENCIA EJECUTIVA DEL CONSEJO | O5: 100 | P5: PRESIDENCIA DEL CONSEJO DE ADMINISTRACION | Q5: 1000 | R5: PRESIDENCIA DEL CONSEJO DE ADMINISTRACION | S5: 10000 | T5: PRESIDENCIA DEL CONSEJO DE ADMINISTRACION | U5: 100000 | V5: PRESIDENCIA DEL CONSEJO DE ADMINISTRACION | W5: 100101 | X5: CORPORATIVO | Y5: 4 | Z5: CORPORATIVO | AA5: 1 | AB5: NEGOCIO EN MARCHA | AC5: 1 | AD5: BANCO | AE5: 1 | AF5: BACK | AG5: 100101 | AH5: CORPORATIVO | AI5: LBARRERA@BANCOBASE.COM | AJ5: 31444
A6: DLOZA | B6: 604 | C6: DIANA LOZA ALVAREZ | D6: 191 | E6: ASISTENTE DE PRESIDENCIA | F6: MONTERREY | G6: 1 | H6: LORENZO BARRERA SEGOVIA | I6: 1 | J6: PRESIDENTE EJECUTIVO | K6: 1 | L6: PRESIDENCIA EJECUTIVA DEL CONSEJO | M6: 10 | N6: PRESIDENCIA EJECUTIVA DEL CONSEJO | O6: 100 | P6: PRESIDENCIA DEL CONSEJO DE ADMINISTRACION | Q6: 1000 | R6: PRESIDENCIA DEL CONSEJO DE ADMINISTRACION | S6: 10000 | T6: PRESIDENCIA DEL CONSEJO DE ADMINISTRACION | U6: 100000 | V6: PRESIDENCIA DEL CONSEJO DE ADMINISTRACION | W6: 100101 | X6: CORPORATIVO | Y6: 4 | Z6: CORPORATIVO | AA6: 1 | AB6: NEGOCIO EN MARCHA | AC6: 1 | AD6: BANCO | AE6: 1 | AF6: BACK | AG6: 100101 | AH6: CORPORATIVO | AI6: DLOZA@BANCOBASE.COM | AJ6: 40273
A7: LARRAMBIDE | B7: 856 | C7: LIZETH ARRAMBIDE ORTIZ | D7: 9130 | E7: ASISTENTE DE PRESIDENCIA | F7: MONTERREY | G7: 1 | H7: LORENZO BARRERA SEGOVIA | I7: 1 | J7: PRESIDENTE EJECUTIVO | K7: 1 | L7: PRESIDENCIA EJECUTIVA DEL CONSEJO | M7: 10 | N7: PRESIDENCIA EJECUTIVA DEL CONSEJO | O7: 100 | P7: PRESIDENCIA DEL CONSEJO DE ADMINISTRACION | Q7: 1000 | R7: PRESIDENCIA DEL CONSEJO DE ADMINISTRACION | S7: 10000 | T7: PRESIDENCIA DEL CONSEJO DE ADMINISTRACION | U7: 100000 | V7: PRESIDENCIA DEL CONSEJO DE ADMINISTRACION | W7: 100101 | X7: CORPORATIVO | Y7: 4 | Z7: CORPORATIVO | AA7: 1 | AB7: NEGOCIO EN MARCHA | AC7: 1 | AD7: BANCO | AE7: 1 | AF7: BACK | AG7: 100101 | AH7: CORPORATIVO | AI7: LARRAMBIDE@BANCOBASE.COM | AJ7: 44186
A8: VCASTILLO | B8: 237 | C8: VICTOR MANUEL CASTILLO TAMEZ | D8: 9449 | E8: CHOFER | F8: MONTERREY | G8: 1 | H8: LORENZO BARRERA SEGOVIA | I8: 1 | J8: PRESIDENTE EJECUTIVO | K8: 1 | L8: PRESIDENCIA EJECUTIVA DEL CONSEJO | M8: 10 | N8: PRESIDENCIA EJECUTIVA DEL CONSEJO | O8: 100 | P8: PRESIDENCIA DEL CONSEJO DE ADMINISTRACION | Q8: 1000 | R8: PRESIDENCIA DEL CONSEJO DE ADMINISTRACION | S8: 10000 | T8: PRESIDENCIA DEL CONSEJO DE ADMINISTRACION | U8: 100000 | V8: PRESIDENCIA DEL CONSEJO DE ADMINISTRACION | W8: 100101 | X8: CORPORATIVO | Y8: 4 | Z8: CORPORATIVO | AA8: 1 | AB8: NEGOCIO EN MARCHA | AC8: 1 | AD8: BANCO | AE8: 1 | AF8: BACK | AG8: 100101 | AH8: CORPORATIVO | AI8: VCASTILLO@BANCOBASE.COM | AJ8: 37849
A9: ABARRERA | B9: 2 | C9: ALVARO BARRERA SEGOVIA | D9: 3 | E9: VICEPRESIDENTE DEL CONSEJO DE ADMINISTRACION | F9: MONTERREY | G9: 1 | H9: LORENZO BARRERA SEGOVIA | I9: 1 | J9: PRESIDENTE EJECUTIVO | K9: 1 | L9: PRESIDENCIA EJECUTIVA DEL CONSEJO | M9: 20 | N9: VICEPRESIDENCIA DEL CONSEJO DE ADMINISTRACION | O9: 200 | P9: VICEPRESIDENCIA DEL CONSEJO DE ADMINISTRACION | Q9: 2000 | R9: VICEPRESIDENCIA DEL CONSEJO DE ADMINISTRACION | S9: 20000 | T9: VICEPRESIDENCIA DEL CONSEJO DE ADMINISTRACION | U9: 200000 | V9: VICEPRESIDENCIA DEL CONSEJO DE ADMINISTRACION | W9: 100101 | X9: CORPORATIVO | Y9: 4 | Z9: CORPORATIVO | AA9: 1 | AB9: NEGOCIO EN MARCHA | AC9: 1 | AD9: BANCO | AE9: 1 | AF9: BACK | AG9: 100101 | AH9: CORPORATIVO | AI9: ABARRERA@BANCOBASE.COM | AJ9: 31625
A10: AVILLARREA | B10: 509 | C10: ALEJANDRA VILLARREAL MORALES | D10: 5393 | E10: ASISTENTE DE VICEPRESIDENCIA | F10: MONTERREY | G10: 2 | H10: ALVARO BARRERA SEGOVIA | I10: 3 | J10: VICEPRESIDENTE DEL CONSEJO DE ADMINISTRACION | K10: 1 | L10: PRESIDENCIA EJECUTIVA DEL CONSEJO | M10: 20 | N10: VICEPRESIDENCIA DEL CONSEJO DE ADMINISTRACION | O10: 200 | P10: VICEPRESIDENCIA DEL CONSEJO DE ADMINISTRACION | Q10: 2000 | R10: VICEPRESIDENCIA DEL CONSEJO DE ADMINISTRACION | S10: 20000 | T10: VICEPRESIDENCIA DEL CONSEJO DE ADMINISTRACION | U10: 200000 | V10: VICEPRESIDENCIA DEL CONSEJO DE ADMINISTRACION | W10: 100101 | X10: CORPORATIVO | Y10: 4 | Z10: CORPORATIVO | AA10: 1 | AB10: NEGOCIO EN MARCHA | AC10: 1 | AD10: BANCO | AE10: 1 | AF10: BACK | AG10: 100101 | AH10: CORPORATIVO | AI10: AVILLARREA@BANCOBASE.COM | AJ10: 39696
A11: OPEREZC | B11: 99526 | C11: ORLANDO PATRICIO PEREZ CARDENAS | D11: 7009 | E11: PRACTICANTE | F11: MONTERREY | G11: 509 | H11: ALEJANDRA VILLARREAL MORALES | I11: 5393 | J11: ASISTENTE DE VICEPRESIDENCIA | K11: 1 | L11: PRESIDENCIA EJECUTIVA DEL CONSEJO | M11: 20 | N11: VICEPRESIDENCIA DEL CONSEJO DE ADMINISTRACION | O11: 200 | P11: VICEPRESIDENCIA DEL CONSEJO DE ADMINISTRACION | Q11: 2000 | R11: VICEPRESIDENCIA DEL CONSEJO DE ADMINISTRACION | S11: 20000 | T11: VICEPRESIDENCIA DEL CONSEJO DE ADMINISTRACION | U11: 200000 | V11: VICEPRESIDENCIA DEL CONSEJO DE ADMINISTRACION | W11: 100101 | X11: CORPORATIVO | Y11: 4 | Z11: CORPORATIVO | AA11: 1 | AB11: NEGOCIO EN MARCHA | AC11: 1 | AD11: BANCO | AE11: 1 | AF11: BACK | AG11: 100101 | AH11: CORPORATIVO | AI11: OPEREZC@BANCOBASE.COM | AJ11: 46041
A12: RTOBIAS | B12: 750 | C12: RODRIGO TOBIAS CASTILLEJA | D12: 10296 | E12: CHOFER | F12: MONTERREY | G12: 2 | H12: ALVARO BARRERA SEGOVIA | I12: 3 | J12: VICEPRESIDENTE DEL CONSEJO DE ADMINISTRACION | K12: 1 | L12: PRESIDENCIA EJECUTIVA DEL CONSEJO | M12: 20 | N12: VICEPRESIDENCIA DEL CONSEJO DE ADMINISTRACION | O12: 200 | P12: VICEPRESIDENCIA DEL CONSEJO DE ADMINISTRACION | Q12: 2000 | R12: VICEPRESIDENCIA DEL CONSEJO DE ADMINISTRACION | S12: 20000 | T12: VICEPRESIDENCIA DEL CONSEJO DE ADMINISTRACION | U12: 200000 | V12: VICEPRESIDENCIA DEL CONSEJO DE ADMINISTRACION | W12: 100101 | X12: CORPORATIVO | Y12: 4 | Z12: CORPORATIVO | AA12: 1 | AB12: NEGOCIO EN MARCHA | AC12: 1 | AD12: BANCO | AE12: 1 | AF12: BACK | AG12: 100101 | AH12: CORPORATIVO | AI12: RTOBIAS@BANCOBASE.COM | AJ12: 40710
A13: OFELIX | B13: 172 | C13: OMAR PAUL FELIX BOJORQUEZ | D13: 9518 | E13: ESPECIALISTA DE GESTION | F13: MONTERREY | G13: 2 | H13: ALVARO BARRERA SEGOVIA | I13: 3 | J13: VICEPRESIDENTE DEL CONSEJO DE ADMINISTRACION | K13: 1 | L13: PRESIDENCIA EJECUTIVA DEL CONSEJO | M13: 20 | N13: VICEPRESIDENCIA DEL CONSEJO DE ADMINISTRACION | O13: 200 | P13: VICEPRESIDENCIA DEL CONSEJO DE ADMINISTRACION | Q13: 2000 | R13: VICEPRESIDENCIA DEL CONSEJO DE ADMINISTRACION | S13: 20000 | T13: VICEPRESIDENCIA DEL CONSEJO DE ADMINISTRACION | U13: 200000 | V13: VICEPRESIDENCIA DEL CONSEJO DE ADMINISTRACION | W13: 100101 | X13: CORPORATIVO | Y13: 4 | Z13: CORPORATIVO | AA13: 1 | AB13: NEGOCIO EN MARCHA | AC13: 1 | AD13: BANCO | AE13: 1 | AF13: BACK | AG13: 100101 | AH13: CORPORATIVO | AI13: OFELIX@BANCOBASE.COM | AJ13: 36846
A14: JESCANDON | B14: 386 | C14: JULIO RICARDO ESCANDON JIMENEZ | D14: 10324 | E14: DIRECTOR GENERAL | F14: MONTERREY | G14: 1 | H14: LORENZO BARRERA SEGOVIA | I14: 1 | J14: PRESIDENTE EJECUTIVO | K14: 1 | L14: PRESIDENCIA EJECUTIVA DEL CONSEJO | M14: 40 | N14: DIRECCION GENERAL BANCO BASE | O14: 400 | P14: DIRECCION GENERAL | Q14: 4000 | R14: DIRECCION GENERAL | S14: 40000 | T14: DIRECCION GENERAL | U14: 400000 | V14: DIRECCION GENERAL | W14: 100101 | X14: CORPORATIVO | Y14: 4 | Z14: CORPORATIVO | AA14: 1 | AB14: NEGOCIO EN MARCHA | AC14: 1 | AD14: BANCO | AE14: 1 | AF14: BACK | AG14: 100101 | AH14: CORPORATIVO | AI14: JESCANDON@BANCOBASE.COM | AJ14: 39114
A15: NYANEZ | B15: 3737 | C15: NANCY YANEZ ANAYA | D15: 194 | E15: ASISTENTE DE DIRECCION GENERAL | F15: MONTERREY | G15: 386 | H15: JULIO RICARDO ESCANDON JIMENEZ | I15: 10324 | J15: DIRECTOR GENERAL | K15: 1 | L15: PRESIDENCIA EJECUTIVA DEL CONSEJO | M15: 40 | N15: DIRECCION GENERAL BANCO BASE | O15: 400 | P15: DIRECCION GENERAL | Q15: 4000 | R15: DIRECCION GENERAL | S15: 40000 | T15: DIRECCION GENERAL | U15: 400000 | V15: DIRECCION GENERAL | W15: 100101 | X15: CORPORATIVO | Y15: 4 | Z15: CORPORATIVO | AA15: 1 | AB15: NEGOCIO EN MARCHA | AC15: 1 | AD15: BANCO | AE15: 1 | AF15: BACK | AG15: 100101 | AH15: CORPORATIVO | AI15: NYANEZ@BANCOBASE.COM | AJ15: 46031
A16: LBARRERAJ | B16: 1694 | C16: LORENZO BARRERA JAIME | D16: 9953 | E16: DIRECTOR GENERAL ADJUNTO DE PRODUCTO Y TRANSFORMACION | F16: MONTERREY | G16: 386 | H16: JULIO RICARDO ESCANDON JIMENEZ | I16: 10324 | J16: DIRECTOR GENERAL | K16: 1 | L16: PRESIDENCIA EJECUTIVA DEL CONSEJO | M16: 30 | N16: DIRECCION GENERAL ADJUNTA PRODUCTO Y TRANSFORMACIO | O16: 300 | P16: DIRECCION GENERAL ADJUNTA PRODUCTO Y TRANSFORMACIO | Q16: 3000 | R16: DIRECCION GENERAL ADJUNTA PRODUCTO Y TRANSFORMACIO | S16: 30000 | T16: DIRECCION GENERAL ADJUNTA PRODUCTO Y TRANSFORMACIO | U16: 300000 | V16: DIRECCION GENERAL ADJUNTA PRODUCTO Y TRANSFORMACIO | W16: 100101 | X16: CORPORATIVO | Y16: 4 | Z16: CORPORATIVO | AA16: 1 | AB16: NEGOCIO EN MARCHA | AC16: 1 | AD16: BANCO | AE16: 1 | AF16: BACK | AG16: 100101 | AH16: CORPORATIVO | AI16: LBARRERAJ@BANCOBASE.COM | AJ16: 42755
A17: GMARTINEZS | B17: 3165 | C17: GLORIA MARIBEL MARTINEZ SEPULVEDA | D17: 10397 | E17: ASISTENTE DE DIRECCION | F17: MONTERREY | G17: 1694 | H17: LORENZO BARRERA JAIME | I17: 9953 | J17: DIRECTOR GENERAL ADJUNTO DE PRODUCTO Y TRANSFORMACION | K17: 1 | L17: PRESIDENCIA EJECUTIVA DEL CONSEJO | M17: 30 | N17: DIRECCION GENERAL ADJUNTA PRODUCTO Y TRANSFORMACIO | O17: 300 | P17: DIRECCION GENERAL ADJUNTA PRODUCTO Y TRANSFORMACIO | Q17: 3000 | R17: DIRECCION GENERAL ADJUNTA PRODUCTO Y TRANSFORMACIO | S17: 30000 | T17: DIRECCION GENERAL ADJUNTA PRODUCTO Y TRANSFORMACIO | U17: 300000 | V17: DIRECCION GENERAL ADJUNTA PRODUCTO Y TRANSFORMACIO | W17: 100101 | X17: CORPORATIVO | Y17: 4 | Z17: CORPORATIVO | AA17: 1 | AB17: NEGOCIO EN MARCHA | AC17: 1 | AD17: BANCO | AE17: 1 | AF17: BACK | AG17: 100101 | AH17: CORPORATIVO | AI17: GMARTINEZS@BANCOBASE.COM | AJ17: 45489
... A68: BVAZQUEZM | B68: 3961 | C68: BELINDA VAZQUEZ MADRIGAL | D68: 9123 | E68: ANALISTA DE SOPORTE ADMINISTRATIVO | F68: MONTERREY | G68: 3162 | H68: MONTSERRAT LOPEZ GARCIA | I68: 5077 | J68: COORDINADOR DE ABASTECIMIENTOS | K68: 1 | L68: PRESIDENCIA EJECUTIVA DEL CONSEJO | M68: 40 | N68: DIRECCION GENERAL BANCO BASE | O68: 420 | P68: DIRECCION ADMINISTRACION Y FINANZAS | Q68: 4220 | R68: DIRECCION DE ADMINISTRACION | S68: 42240 | T68: SUBDIRECCION DE COMPRAS Y HABILITACION DE ESPACIOS | U68: 422316 | V68: GERENCIA CONTROL DE GASTOS Y ABASTECIMIENTO | W68: 100101 | X68: CORPORATIVO | Y68: 4 | Z68: CORPORATIVO | AA68: 1 | AB68: NEGOCIO EN MARCHA | AC68: 1 | AD68: BANCO | AE68: 1 | AF68: BACK | AG68: 100101 | AH68: CORPORATIVO | AI68: BVAZQUEZM@BANCOBASE.COM | AJ68: 46237
A69: ACRUZY | B69: 2977 | C69: LUIS ALEJANDRO DE LA CRUZ YAÑEZ | D69: 9626 | E69: AUXILIAR DE SEGURIDAD | F69: MONTERREY | I69: 9010 | J69: COORDINADOR DE SEGURIDAD | K69: 1 | L69: PRESIDENCIA EJECUTIVA DEL CONSEJO | M69: 40 | N69: DIRECCION GENERAL BANCO BASE | O69: 420 | P69: DIRECCION ADMINISTRACION Y FINANZAS | Q69: 4220 | R69: DIRECCION DE ADMINISTRACION | S69: 42240 | T69: SUBDIRECCION DE COMPRAS Y HABILITACION DE ESPACIOS | U69: 422320 | V69: SEGURIDAD CORPORATIVA | W69: 100101 | X69: CORPORATIVO | Y69: 4 | Z69: CORPORATIVO | AA69: 1 | AB69: NEGOCIO EN MARCHA | AC69: 1 | AD69: BANCO | AE69: 1 | AF69: BACK | AG69: 100101 | AH69: CORPORATIVO | AI69: ACRUZY@BANCOBASE.COM | AJ69: 45231
A70: AGALLEGOS | B70: 756 | C70: AMELIA GALLEGOS GALVAN | D70: 47 | E70: GERENTE DE CONTABILIDAD | F70: MONTERREY | G70: 209 | H70: ROBERTO MUÑOZ SALAZAR | I70: 9463 | J70: DIRECTOR DE ADMINISTRACION | K70: 1 | L70: PRESIDENCIA EJECUTIVA DEL CONSEJO | M70: 40 | N70: DIRECCION GENERAL BANCO BASE | O70: 420 | P70: DIRECCION ADMINISTRACION Y FINANZAS | Q70: 4220 | R70: DIRECCION DE ADMINISTRACION | S70: 42210 | T70: GERENCIA DE CONTABILIDAD | U70: 422101 | V70: CONTABILIDAD | W70: 100101 | X70: CORPORATIVO | Y70: 4 | Z70: CORPORATIVO | AA70: 1 | AB70: NEGOCIO EN MARCHA | AC70: 1 | AD70: BANCO | AE70: 1 | AF70: BACK | AG70: 100101 | AH70: CORPORATIVO | AI70: AGALLEGOS@BANCOBASE.COM | AJ70: 40725
A71: AHERNANDES | B71: 1056 | C71: ARACELI HERNANDEZ SANCHEZ | D71: 8384 | E71: COORDINADOR DE CONTABILIDAD | F71: MONTERREY | G71: 756 | H71: AMELIA GALLEGOS GALVAN | I71: 47 | J71: GERENTE DE CONTABILIDAD | K71: 1 | L71: PRESIDENCIA EJECUTIVA DEL CONSEJO | M71: 40 | N71: DIRECCION GENERAL BANCO BASE | O71: 420 | P71: DIRECCION ADMINISTRACION Y FINANZAS | Q71: 4220 | R71: DIRECCION DE ADMINISTRACION | S71: 42210 | T71: GERENCIA DE CONTABILIDAD | U71: 422101 | V71: CONTABILIDAD | W71: 100101 | X71: CORPORATIVO | Y71: 4 | Z71: CORPORATIVO | AA71: 1 | AB71: NEGOCIO EN MARCHA | AC71: 1 | AD71: BANCO | AE71: 1 | AF71: BACK | AG71: 100101 | AH71: CORPORATIVO | AI71: AHERNANDES@BANCOBASE.COM | AJ71: 41502
A72: ASALINASV | B72: 3006 | C72: ALONDRA MONSERRAT SALINAS VARGAS | D72: 8275 | E72: ANALISTA CONTABLE | F72: MONTERREY | G72: 1056 | H72: ARACELI HERNANDEZ SANCHEZ | I72: 8384 | J72: COORDINADOR DE CONTABILIDAD | K72: 1 | L72: PRESIDENCIA EJECUTIVA DEL CONSEJO | M72: 40 | N72: DIRECCION GENERAL BANCO BASE | O72: 420 | P72: DIRECCION ADMINISTRACION Y FINANZAS | Q72: 4220 | R72: DIRECCION DE ADMINISTRACION | S72: 42210 | T72: GERENCIA DE CONTABILIDAD | U72: 422101 | V72: CONTABILIDAD | W72: 100101 | X72: CORPORATIVO | Y72: 4 | Z72: CORPORATIVO | AA72: 1 | AB72: NEGOCIO EN MARCHA | AC72: 1 | AD72: BANCO | AE72: 1 | AF72: BACK | AG72: 100101 | AH72: CORPORATIVO | AI72: ASALINASV@BANCOBASE.COM | AJ72: 45293
A73: EPENA | B73: 2074 | C73: CYNTHIA ESTHELA PEÑA MARTINEZ | D73: 8385 | E73: COORDINADOR DE CONTABILIDAD | F73: MONTERREY | G73: 756 | H73: AMELIA GALLEGOS GALVAN | I73: 47 | J73: GERENTE DE CONTABILIDAD | K73: 1 | L73: PRESIDENCIA EJECUTIVA DEL CONSEJO | M73: 40 | N73: DIRECCION GENERAL BANCO BASE | O73: 420 | P73: DIRECCION ADMINISTRACION Y FINANZAS | Q73: 4220 | R73: DIRECCION DE ADMINISTRACION | S73: 42210 | T73: GERENCIA DE CONTABILIDAD | U73: 422101 | V73: CONTABILIDAD | W73: 100101 | X73: CORPORATIVO | Y73: 4 | Z73: CORPORATIVO | AA73: 1 | AB73: NEGOCIO EN MARCHA | AC73: 1 | AD73: BANCO | AE73: 1 | AF73: BACK | AG73: 100101 | AH73: CORPORATIVO | AI73: EPENA@BANCOBASE.COM | AJ73: 43328
A74: ACANO | B74: 2884 | C74: AXEL JOAN CANO ESPINOZA | D74: 8134 | E74: ANALISTA CONTABLE | F74: MONTERREY | G74: 2074 | H74: CYNTHIA ESTHELA PEÑA MARTINEZ | I74: 8385 | J74: COORDINADOR DE CONTABILIDAD | K74: 1 | L74: PRESIDENCIA EJECUTIVA DEL CONSEJO | M74: 40 | N74: DIRECCION GENERAL BANCO BASE | O74: 420 | P74: DIRECCION ADMINISTRACION Y FINANZAS | Q74: 4220 | R74: DIRECCION DE ADMINISTRACION | S74: 42210 | T74: GERENCIA DE CONTABILIDAD | U74: 422101 | V74: CONTABILIDAD | W74: 100101 | X74: CORPORATIVO | Y74: 4 | Z74: CORPORATIVO | AA74: 1 | AB74: NEGOCIO EN MARCHA | AC74: 1 | AD74: BANCO | AE74: 1 | AF74: BACK | AG74: 100101 | AH74: CORPORATIVO | AI74: ACANO@BANCOBASE.COM | AJ74: 45047
